export const catchAsyncError=(theFunction)=>{
    return(req,res,next)=>{
       Promise.resolve(theFunction(req,res,next)).catch(next);
    };
};

explain------------------------------------------------------------------------------------------------------------------------------------------------------------------------------------


The catchAsyncError function is a higher-order function (a function that returns another function) designed to handle asynchronous errors 
in Express.js routes or middleware. Here's a detailed explanation of how it works and why it's useful:

Purpose------------------------------------------------------------------------------------------------------------------------------------------------------------------------------------
In Express.js, error handling in asynchronous routes or middleware can be tricky. If an asynchronous function throws an error or rejects a promise, 
it won't be caught by Express's default error handling mechanism. The catchAsyncError function simplifies this by ensuring that any errors in the 
asynchronous function are properly caught and passed to the next middleware or error handler.

Explanation
Let's break down the code:

javascript
Copy code------------------------------------------------------

export const catchAsyncError = (theFunction) => {
  return (req, res, next) => {
    Promise.resolve(theFunction(req, res, next)).catch(next);
  };
};
Higher-Order Function:

javascript
Copy code------------------------------------------------------

export const catchAsyncError = (theFunction) => {
This line defines a function named catchAsyncError that takes a single argument theFunction. This argument is expected to be an asynchronous function (an Express.js route or middleware).

Return a New Function:

javascript
Copy code------------------------------------------------------

return (req, res, next) => {
The catchAsyncError function returns a new function. This returned function is the actual Express.js middleware that will be executed when a request is made.

Execute the Original Function and Handle Errors:

javascript
Copy code------------------------------------------------------

Promise.resolve(theFunction(req, res, next)).catch(next);
theFunction(req, res, next): This calls the original asynchronous function with the Express.js req, res, and next arguments.
Promise.resolve(...): Wrapping the function call in Promise.resolve ensures that the result is always a promise. This is useful because theFunction might not explicitly return a promise if it's an async function.
.catch(next): This catches any errors that occur during the execution of theFunction. If an error is caught, it passes the error to the next middleware function (typically an error handler) using next.


Usage---------------------------------------------------------------------------------------------------------------------------------------------------------------------------------------

Here's how you might use catchAsyncError in an Express.js route:

Without catchAsyncError
Without using catchAsyncError, you would need to use try and catch blocks manually:

javascript
Copy code------------------------------------------------------

app.get('/some-route', async (req, res, next) => {
  try {
    const result = await someAsyncFunction();
    res.json(result);
  } catch (error) {
    next(error);
  }
});

With catchAsyncError
Using catchAsyncError, you can simplify this:

javascript
Copy code------------------------------------------------------

import { catchAsyncError } from './path/to/catchAsyncError';

app.get('/some-route', catchAsyncError(async (req, res, next) => {
  const result = await someAsyncFunction();
  res.json(result);
}));


Benefits----------------------------------

Simplifies Code: Reduces boilerplate code by eliminating the need for repetitive try and catch blocks.
Consistent Error Handling: Ensures that all errors, including asynchronous ones, are properly passed to the Express error handling middleware.
Improves Readability: Makes route handlers cleaner and easier to read by focusing on the core logic rather than error handling.
Complete Example
Hereâ€™s a complete example with an Express application:

catchAsyncError.js
javascript
Copy code
export const catchAsyncError = (theFunction) => {
  return (req, res, next) => {
    Promise.resolve(theFunction(req, res, next)).catch(next);
  };
};
app.js
javascript
Copy code
import express from 'express';
import { catchAsyncError } from './catchAsyncError.js';

const app = express();

app.get('/some-route', catchAsyncError(async (req, res, next) => {
  const result = await someAsyncFunction();
  res.json(result);
}));

app.use((err, req, res, next) => {
  res.status(500).json({ success: false, message: err.message });
});

const someAsyncFunction = async () => {
  // Simulate an asynchronous operation
  return { data: 'Hello, world!' };
};

app.listen(3000, () => {
  console.log('Server is running on port 3000');
});
In this example, the catchAsyncError function ensures that any errors occurring within the asynchronous route handler are caught and passed to the error handling middleware, which responds with a 500 status code and an error message.